Workbook

Sheet Критерии
A1: Критерии выбора и шкалы
A3: Все критерии — выгоды: чем выше оценка, тем лучше (1…9).
A5: Код | B5: Критерий | C5: Как оценивать | D5: Якоря шкалы
A6: K1 | B6: Полезность для студентов | C6: Насколько решение закрывает частую и понятную потребность целевой аудитории | D6: 1 — сомнительная ценность; 9 — высокая ценность
A7: K2 | B7: Реализуемость MVP | C7: Насколько реально выполнить 12 UC силами трёх человек без платных интеграций | D7: 1 — трудно выполнить; 9 — легко выполнить
A8: K3 | B8: Простота проверки и демонстрации | C8: Насколько легко написать тест-кейсы и показать сквозной сценарий | D8: 1 — трудно проверить; 9 — наглядное демо
A9: K4 | B9: Доступность тестовых данных | C9: Можно ли безопасно сгенерировать реалистичные учебные данные и роли | D9: 1 — данных почти нет; 9 — доступны без ограничений
A10: K5 | B10: Потенциал дальнейшего развития | C10: Можно ли добавить функции после MVP без радикальной смены архитектуры | D10: 1 — почти нет развития; 9 — большой потенциал
A13: Методическое правило
A14: Сначала участники независимо выставляют по одному баллу 1–9 за важность K1–K5 и каждую альтернативу по каждому критерию. Три балла сортируются: min/median/max → (пессимистичная, ожидаемая, оптимистичная) оценка.

Sheet Концепции
A1: Четыре концепции — по 12 Use Cases
A5: Код | B5: Концепция | C5: Use Case | D5: Основной актор | E5: Краткий сценарий
A6: A1 | B6: StudyFlow | C6: UC-01 | D6: Студент | E6: Войти в личный кабинет
A7: A1 | B7: StudyFlow | C7: UC-02 | D7: Студент | E7: Создать учебную команду
A8: A1 | B8: StudyFlow | C8: UC-03 | D8: Студент | E8: Пригласить участника в команду
A9: A1 | B9: StudyFlow | C9: UC-04 | D9: Участник команды | E9: Создать проект
A10: A1 | B10: StudyFlow | C10: UC-05 | D10: Участник команды | E10: Добавить задачу
A11: A1 | B11: StudyFlow | C11: UC-06 | D11: Участник команды | E11: Назначить исполнителя задачи
A12: A1 | B12: StudyFlow | C12: UC-07 | D12: Участник команды | E12: Установить срок задачи
A13: A1 | B13: StudyFlow | C13: UC-08 | D13: Исполнитель | E13: Изменить статус задачи
A14: A1 | B14: StudyFlow | C14: UC-09 | D14: Участник команды | E14: Оставить комментарий к задаче
A15: A1 | B15: StudyFlow | C15: UC-10 | D15: Участник команды | E15: Отфильтровать задачи по статусу
A16: A1 | B16: StudyFlow | C16: UC-11 | D16: Участник команды | E16: Просмотреть задачи на календаре
... A53: A4 | B53: SkillBridge | C53: UC-12 | D53: Студент | E53: Оставить отзыв по консультации

Sheet Оценки
A1: Оценки трёх участников
A4: Тип | B4: Вариант | C4: Код | D4: Критерий | E4: Участник 1 | F4: Участник 2 | G4: Участник 3 | H4: Песс. min | I4: Ожид. median | J4: Оптим. max
A5: Важность | B5: — | C5: K1 | D5: Ценность для студентов | E5: 9 | F5: 8 | G5: 9 | H5: =MIN(E5:G5) -> 8 | I5: =MEDIAN(E5:G5) -> 9 | J5: =MAX(E5:G5) -> 9
A6: Важность | B6: — | C6: K2 | D6: Реализуемость MVP | E6: 8 | F6: 9 | G6: 8 | H6: =MIN(E6:G6) -> 8 | I6: =MEDIAN(E6:G6) -> 8 | J6: =MAX(E6:G6) -> 9
A7: Важность | B7: — | C7: K3 | D7: Проверяемость и демо | E7: 8 | F7: 7 | G7: 8 | H7: =MIN(E7:G7) -> 7 | I7: =MEDIAN(E7:G7) -> 8 | J7: =MAX(E7:G7) -> 8
A8: Важность | B8: — | C8: K4 | D8: Доступность тестовых данных | E8: 6 | F8: 7 | G8: 7 | H8: =MIN(E8:G8) -> 6 | I8: =MEDIAN(E8:G8) -> 7 | J8: =MAX(E8:G8) -> 7
A9: Важность | B9: — | C9: K5 | D9: Потенциал развития | E9: 6 | F9: 5 | G9: 6 | H9: =MIN(E9:G9) -> 5 | I9: =MEDIAN(E9:G9) -> 6 | J9: =MAX(E9:G9) -> 6
A10: Альтернатива | B10: A1 | C10: K1 | D10: Ценность для студентов | E10: 7 | F10: 8 | G10: 7 | H10: =MIN(E10:G10) -> 7 | I10: =MEDIAN(E10:G10) -> 7 | J10: =MAX(E10:G10) -> 8
A11: Альтернатива | B11: A1 | C11: K2 | D11: Реализуемость MVP | E11: 9 | F11: 8 | G11: 9 | H11: =MIN(E11:G11) -> 8 | I11: =MEDIAN(E11:G11) -> 9 | J11: =MAX(E11:G11) -> 9
A12: Альтернатива | B12: A1 | C12: K3 | D12: Проверяемость и демо | E12: 9 | F12: 9 | G12: 8 | H12: =MIN(E12:G12) -> 8 | I12: =MEDIAN(E12:G12) -> 9 | J12: =MAX(E12:G12) -> 9
A13: Альтернатива | B13: A1 | C13: K4 | D13: Доступность тестовых данных | E13: 9 | F13: 9 | G13: 8 | H13: =MIN(E13:G13) -> 8 | I13: =MEDIAN(E13:G13) -> 9 | J13: =MAX(E13:G13) -> 9
A14: Альтернатива | B14: A1 | C14: K5 | D14: Потенциал развития | E14: 5 | F14: 4 | G14: 5 | H14: =MIN(E14:G14) -> 4 | I14: =MEDIAN(E14:G14) -> 5 | J14: =MAX(E14:G14) -> 5
A15: Альтернатива | B15: A2 | C15: K1 | D15: Ценность для студентов | E15: 9 | F15: 9 | G15: 8 | H15: =MIN(E15:G15) -> 8 | I15: =MEDIAN(E15:G15) -> 9 | J15: =MAX(E15:G15) -> 9
A16: Альтернатива | B16: A2 | C16: K2 | D16: Реализуемость MVP | E16: 8 | F16: 7 | G16: 8 | H16: =MIN(E16:G16) -> 7 | I16: =MEDIAN(E16:G16) -> 8 | J16: =MAX(E16:G16) -> 8
... A29: Альтернатива | B29: A4 | C29: K5 | D29: Потенциал развития | E29: 9 | F29: 8 | G29: 9 | H29: =MIN(E29:G29) -> 8 | I29: =MEDIAN(E29:G29) -> 9 | J29: =MAX(E29:G29) -> 9

Sheet TOPSIS
A1: Нечёткий коллективный TOPSIS
A3: Треугольные числа сортируются из 3 индивидуальных баллов; для выгоды r=(l,m,u)/max_i(u); веса w=(l,m,u)/Σ median.
A4: 1. Треугольные важности и нечёткие веса
A5: Код | B5: Название | C5: l | D5: m | E5: u | F5: w(l) | G5: w(m) | H5: w(u) | I5: max u оценок
A6: K1 | B6: Ценность для студентов | C6: =Оценки!H5 -> 8 | D6: =Оценки!I5 -> 9 | E6: =Оценки!J5 -> 9 | F6: =C6/SUM($D$6:$D$10) -> 0.21052632 | G6: =D6/SUM($D$6:$D$10) -> 0.23684211 | H6: =E6/SUM($D$6:$D$10) -> 0.23684211 | I6: =MAX(E14,E19,E24,E29) -> 9
A7: K2 | B7: Реализуемость MVP | C7: =Оценки!H6 -> 8 | D7: =Оценки!I6 -> 8 | E7: =Оценки!J6 -> 9 | F7: =C7/SUM($D$6:$D$10) -> 0.21052632 | G7: =D7/SUM($D$6:$D$10) -> 0.21052632 | H7: =E7/SUM($D$6:$D$10) -> 0.23684211 | I7: =MAX(E15,E20,E25,E30) -> 9
A8: K3 | B8: Проверяемость и демо | C8: =Оценки!H7 -> 7 | D8: =Оценки!I7 -> 8 | E8: =Оценки!J7 -> 8 | F8: =C8/SUM($D$6:$D$10) -> 0.18421053 | G8: =D8/SUM($D$6:$D$10) -> 0.21052632 | H8: =E8/SUM($D$6:$D$10) -> 0.21052632 | I8: =MAX(E16,E21,E26,E31) -> 9
A9: K4 | B9: Доступность тестовых данных | C9: =Оценки!H8 -> 6 | D9: =Оценки!I8 -> 7 | E9: =Оценки!J8 -> 7 | F9: =C9/SUM($D$6:$D$10) -> 0.15789474 | G9: =D9/SUM($D$6:$D$10) -> 0.18421053 | H9: =E9/SUM($D$6:$D$10) -> 0.18421053 | I9: =MAX(E17,E22,E27,E32) -> 9
A10: K5 | B10: Потенциал развития | C10: =Оценки!H9 -> 5 | D10: =Оценки!I9 -> 6 | E10: =Оценки!J9 -> 6 | F10: =C10/SUM($D$6:$D$10) -> 0.13157895 | G10: =D10/SUM($D$6:$D$10) -> 0.15789474 | H10: =E10/SUM($D$6:$D$10) -> 0.15789474 | I10: =MAX(E18,E23,E28,E33) -> 9
A12: 2. Нормализованная и взвешенная матрица — все 20 строк
A13: Alt | B13: K | C13: x(l) | D13: x(m) | E13: x(u) | F13: max u | G13: r(l) | H13: r(m) | I13: r(u) | J13: w(l) | K13: w(m) | L13: w(u) | M13: v(l) | N13: v(m) | O13: v(u) | P13: d+ | Q13: d−
A14: A1 | B14: K1 | C14: =Оценки!H10 -> 7 | D14: =Оценки!I10 -> 7 | E14: =Оценки!J10 -> 8 | F14: =$I$6 -> 9 | G14: =C14/F14 -> 0.77777778 | H14: =D14/F14 -> 0.77777778 | I14: =E14/F14 -> 0.88888889 | J14: =$F$6 -> 0.21052632 | K14: =$G$6 -> 0.23684211 | L14: =$H$6 -> 0.23684211 | M14: =G14*J14 -> 0.16374269 | N14: =H14*K14 -> 0.18421053 | O14: =I14*L14 -> 0.21052632 | P14: =SQRT(((M14-$B$37)^2+(N14-$B$37)^2+(O14-$B$37)^2)/3) -> 0.054179112 | Q14: =SQRT(((M14-$C$37)^2+(N14-$C$37)^2+(O14-$C$37)^2)/3) -> 0.049650236
A15: A1 | B15: K2 | C15: =Оценки!H11 -> 8 | D15: =Оценки!I11 -> 9 | E15: =Оценки!J11 -> 9 | F15: =$I$7 -> 9 | G15: =C15/F15 -> 0.88888889 | H15: =D15/F15 -> 1 | I15: =E15/F15 -> 1 | J15: =$F$7 -> 0.21052632 | K15: =$G$7 -> 0.21052632 | L15: =$H$7 -> 0.23684211 | M15: =G15*J15 -> 0.1871345 | N15: =H15*K15 -> 0.21052632 | O15: =I15*L15 -> 0.23684211 | P15: =SQRT(((M15-$B$38)^2+(N15-$B$38)^2+(O15-$B$38)^2)/3) -> 0.032472381 | Q15: =SQRT(((M15-$C$38)^2+(N15-$C$38)^2+(O15-$C$38)^2)/3) -> 0.096697753
A16: A1 | B16: K3 | C16: =Оценки!H12 -> 8 | D16: =Оценки!I12 -> 9 | E16: =Оценки!J12 -> 9 | F16: =$I$8 -> 9 | G16: =C16/F16 -> 0.88888889 | H16: =D16/F16 -> 1 | I16: =E16/F16 -> 1 | J16: =$F$8 -> 0.18421053 | K16: =$G$8 -> 0.21052632 | L16: =$H$8 -> 0.21052632 | M16: =G16*J16 -> 0.16374269 | N16: =H16*K16 -> 0.21052632 | O16: =I16*L16 -> 0.21052632 | P16: =SQRT(((M16-$B$39)^2+(N16-$B$39)^2+(O16-$B$39)^2)/3) -> 0.027010539 | Q16: =SQRT(((M16-$C$39)^2+(N16-$C$39)^2+(O16-$C$39)^2)/3) -> 0.075421217
A17: A1 | B17: K4 | C17: =Оценки!H13 -> 8 | D17: =Оценки!I13 -> 9 | E17: =Оценки!J13 -> 9 | F17: =$I$9 -> 9 | G17: =C17/F17 -> 0.88888889 | H17: =D17/F17 -> 1 | I17: =E17/F17 -> 1 | J17: =$F$9 -> 0.15789474 | K17: =$G$9 -> 0.18421053 | L17: =$H$9 -> 0.18421053 | M17: =G17*J17 -> 0.14035088 | N17: =H17*K17 -> 0.18421053 | O17: =I17*L17 -> 0.18421053 | P17: =SQRT(((M17-$B$40)^2+(N17-$B$40)^2+(O17-$B$40)^2)/3) -> 0.02532238 | Q17: =SQRT(((M17-$C$40)^2+(N17-$C$40)^2+(O17-$C$40)^2)/3) -> 0.067568538
A18: A1 | B18: K5 | C18: =Оценки!H14 -> 4 | D18: =Оценки!I14 -> 5 | E18: =Оценки!J14 -> 5 | F18: =$I$10 -> 9 | G18: =C18/F18 -> 0.44444444 | H18: =D18/F18 -> 0.55555556 | I18: =E18/F18 -> 0.55555556 | J18: =$F$10 -> 0.13157895 | K18: =$G$10 -> 0.15789474 | L18: =$H$10 -> 0.15789474 | M18: =G18*J18 -> 0.058479532 | N18: =H18*K18 -> 0.087719298 | O18: =I18*L18 -> 0.087719298 | P18: =SQRT(((M18-$B$41)^2+(N18-$B$41)^2+(O18-$B$41)^2)/3) -> 0.081101926 | Q18: =SQRT(((M18-$C$41)^2+(N18-$C$41)^2+(O18-$C$41)^2)/3) -> 0.023874169
A19: A2 | B19: K1 | C19: =Оценки!H15 -> 8 | D19: =Оценки!I15 -> 9 | E19: =Оценки!J15 -> 9 | F19: =$I$6 -> 9 | G19: =C19/F19 -> 0.88888889 | H19: =D19/F19 -> 1 | I19: =E19/F19 -> 1 | J19: =$F$6 -> 0.21052632 | K19: =$G$6 -> 0.23684211 | L19: =$H$6 -> 0.23684211 | M19: =G19*J19 -> 0.1871345 | N19: =H19*K19 -> 0.23684211 | O19: =I19*L19 -> 0.23684211 | P19: =SQRT(((M19-$B$37)^2+(N19-$B$37)^2+(O19-$B$37)^2)/3) -> 0.028698698 | Q19: =SQRT(((M19-$C$37)^2+(N19-$C$37)^2+(O19-$C$37)^2)/3) -> 0.083286297
A20: A2 | B20: K2 | C20: =Оценки!H16 -> 7 | D20: =Оценки!I16 -> 8 | E20: =Оценки!J16 -> 8 | F20: =$I$7 -> 9 | G20: =C20/F20 -> 0.77777778 | H20: =D20/F20 -> 0.88888889 | I20: =E20/F20 -> 0.88888889 | J20: =$F$7 -> 0.21052632 | K20: =$G$7 -> 0.21052632 | L20: =$H$7 -> 0.23684211 | M20: =G20*J20 -> 0.16374269 | N20: =H20*K20 -> 0.1871345 | O20: =I20*L20 -> 0.21052632 | P20: =SQRT(((M20-$B$38)^2+(N20-$B$38)^2+(O20-$B$38)^2)/3) -> 0.053250637 | Q20: =SQRT(((M20-$C$38)^2+(N20-$C$38)^2+(O20-$C$38)^2)/3) -> 0.072728102
A21: A2 | B21: K3 | C21: =Оценки!H17 -> 8 | D21: =Оценки!I17 -> 9 | E21: =Оценки!J17 -> 9 | F21: =$I$8 -> 9 | G21: =C21/F21 -> 0.88888889 | H21: =D21/F21 -> 1 | I21: =E21/F21 -> 1 | J21: =$F$8 -> 0.18421053 | K21: =$G$8 -> 0.21052632 | L21: =$H$8 -> 0.21052632 | M21: =G21*J21 -> 0.16374269 | N21: =H21*K21 -> 0.21052632 | O21: =I21*L21 -> 0.21052632 | P21: =SQRT(((M21-$B$39)^2+(N21-$B$39)^2+(O21-$B$39)^2)/3) -> 0.027010539 | Q21: =SQRT(((M21-$C$39)^2+(N21-$C$39)^2+(O21-$C$39)^2)/3) -> 0.075421217
A22: A2 | B22: K4 | C22: =Оценки!H18 -> 8 | D22: =Оценки!I18 -> 9 | E22: =Оценки!J18 -> 9 | F22: =$I$9 -> 9 | G22: =C22/F22 -> 0.88888889 | H22: =D22/F22 -> 1 | I22: =E22/F22 -> 1 | J22: =$F$9 -> 0.15789474 | K22: =$G$9 -> 0.18421053 | L22: =$H$9 -> 0.18421053 | M22: =G22*J22 -> 0.14035088 | N22: =H22*K22 -> 0.18421053 | O22: =I22*L22 -> 0.18421053 | P22: =SQRT(((M22-$B$40)^2+(N22-$B$40)^2+(O22-$B$40)^2)/3) -> 0.02532238 | Q22: =SQRT(((M22-$C$40)^2+(N22-$C$40)^2+(O22-$C$40)^2)/3) -> 0.067568538
A23: A2 | B23: K5 | C23: =Оценки!H19 -> 8 | D23: =Оценки!I19 -> 8 | E23: =Оценки!J19 -> 9 | F23: =$I$10 -> 9 | G23: =C23/F23 -> 0.88888889 | H23: =D23/F23 -> 0.88888889 | I23: =E23/F23 -> 1 | J23: =$F$10 -> 0.13157895 | K23: =$G$10 -> 0.15789474 | L23: =$H$10 -> 0.15789474 | M23: =G23*J23 -> 0.11695906 | N23: =H23*K23 -> 0.14035088 | O23: =I23*L23 -> 0.15789474 | P23: =SQRT(((M23-$B$41)^2+(N23-$B$41)^2+(O23-$B$41)^2)/3) -> 0.025713267 | Q23: =SQRT(((M23-$C$41)^2+(N23-$C$41)^2+(O23-$C$41)^2)/3) -> 0.081662222
A24: A3 | B24: K1 | C24: =Оценки!H20 -> 6 | D24: =Оценки!I20 -> 7 | E24: =Оценки!J20 -> 7 | F24: =$I$6 -> 9 | G24: =C24/F24 -> 0.66666667 | H24: =D24/F24 -> 0.77777778 | I24: =E24/F24 -> 0.77777778 | J24: =$F$6 -> 0.21052632 | K24: =$G$6 -> 0.23684211 | L24: =$H$6 -> 0.23684211 | M24: =G24*J24 -> 0.14035088 | N24: =H24*K24 -> 0.18421053 | O24: =I24*L24 -> 0.18421053 | P24: =SQRT(((M24-$B$37)^2+(N24-$B$37)^2+(O24-$B$37)^2)/3) -> 0.07035795 | Q24: =SQRT(((M24-$C$37)^2+(N24-$C$37)^2+(O24-$C$37)^2)/3) -> 0.035811254
A25: A3 | B25: K2 | C25: =Оценки!H21 -> 8 | D25: =Оценки!I21 -> 8 | E25: =Оценки!J21 -> 9 | F25: =$I$7 -> 9 | G25: =C25/F25 -> 0.88888889 | H25: =D25/F25 -> 0.88888889 | I25: =E25/F25 -> 1 | J25: =$F$7 -> 0.21052632 | K25: =$G$7 -> 0.21052632 | L25: =$H$7 -> 0.23684211 | M25: =G25*J25 -> 0.1871345 | N25: =H25*K25 -> 0.1871345 | O25: =I25*L25 -> 0.23684211 | P25: =SQRT(((M25-$B$38)^2+(N25-$B$38)^2+(O25-$B$38)^2)/3) -> 0.040586087 | Q25: =SQRT(((M25-$C$38)^2+(N25-$C$38)^2+(O25-$C$38)^2)/3) -> 0.089853822
A26: A3 | B26: K3 | C26: =Оценки!H22 -> 7 | D26: =Оценки!I22 -> 8 | E26: =Оценки!J22 -> 8 | F26: =$I$8 -> 9 | G26: =C26/F26 -> 0.77777778 | H26: =D26/F26 -> 0.88888889 | I26: =E26/F26 -> 0.88888889 | J26: =$F$8 -> 0.18421053 | K26: =$G$8 -> 0.21052632 | L26: =$H$8 -> 0.21052632 | M26: =G26*J26 -> 0.14327485 | N26: =H26*K26 -> 0.1871345 | O26: =I26*L26 -> 0.1871345 | P26: =SQRT(((M26-$B$39)^2+(N26-$B$39)^2+(O26-$B$39)^2)/3) -> 0.043270902 | Q26: =SQRT(((M26-$C$39)^2+(N26-$C$39)^2+(O26-$C$39)^2)/3) -> 0.053836119
A27: A3 | B27: K4 | C27: =Оценки!H23 -> 7 | D27: =Оценки!I23 -> 8 | E27: =Оценки!J23 -> 8 | F27: =$I$9 -> 9 | G27: =C27/F27 -> 0.77777778 | H27: =D27/F27 -> 0.88888889 | I27: =E27/F27 -> 0.88888889 | J27: =$F$9 -> 0.15789474 | K27: =$G$9 -> 0.18421053 | L27: =$H$9 -> 0.18421053 | M27: =G27*J27 -> 0.12280702 | N27: =H27*K27 -> 0.16374269 | O27: =I27*L27 -> 0.16374269 | P27: =SQRT(((M27-$B$40)^2+(N27-$B$40)^2+(O27-$B$40)^2)/3) -> 0.039192923 | Q27: =SQRT(((M27-$C$40)^2+(N27-$C$40)^2+(O27-$C$40)^2)/3) -> 0.048810854
A28: A3 | B28: K5 | C28: =Оценки!H24 -> 7 | D28: =Оценки!I24 -> 7 | E28: =Оценки!J24 -> 8 | F28: =$I$10 -> 9 | G28: =C28/F28 -> 0.77777778 | H28: =D28/F28 -> 0.77777778 | I28: =E28/F28 -> 0.88888889 | J28: =$F$10 -> 0.13157895 | K28: =$G$10 -> 0.15789474 | L28: =$H$10 -> 0.15789474 | M28: =G28*J28 -> 0.10233918 | N28: =H28*K28 -> 0.12280702 | O28: =I28*L28 -> 0.14035088 | P28: =SQRT(((M28-$B$41)^2+(N28-$B$41)^2+(O28-$B$41)^2)/3) -> 0.039265569 | Q28: =SQRT(((M28-$C$41)^2+(N28-$C$41)^2+(O28-$C$41)^2)/3) -> 0.065229368
A29: A4 | B29: K1 | C29: =Оценки!H25 -> 7 | D29: =Оценки!I25 -> 8 | E29: =Оценки!J25 -> 8 | F29: =$I$6 -> 9 | G29: =C29/F29 -> 0.77777778 | H29: =D29/F29 -> 0.88888889 | I29: =E29/F29 -> 0.88888889 | J29: =$F$6 -> 0.21052632 | K29: =$G$6 -> 0.23684211 | L29: =$H$6 -> 0.23684211 | M29: =G29*J29 -> 0.16374269 | N29: =H29*K29 -> 0.21052632 | O29: =I29*L29 -> 0.21052632 | P29: =SQRT(((M29-$B$37)^2+(N29-$B$37)^2+(O29-$B$37)^2)/3) -> 0.047358794 | Q29: =SQRT(((M29-$C$37)^2+(N29-$C$37)^2+(O29-$C$37)^2)/3) -> 0.058868105
A30: A4 | B30: K2 | C30: =Оценки!H26 -> 5 | D30: =Оценки!I26 -> 6 | E30: =Оценки!J26 -> 6 | F30: =$I$7 -> 9 | G30: =C30/F30 -> 0.55555556 | H30: =D30/F30 -> 0.66666667 | I30: =E30/F30 -> 0.66666667 | J30: =$F$7 -> 0.21052632 | K30: =$G$7 -> 0.21052632 | L30: =$H$7 -> 0.23684211 | M30: =G30*J30 -> 0.11695906 | N30: =H30*K30 -> 0.14035088 | O30: =I30*L30 -> 0.15789474 | P30: =SQRT(((M30-$B$38)^2+(N30-$B$38)^2+(O30-$B$38)^2)/3) -> 0.099858546 | Q30: =SQRT(((M30-$C$38)^2+(N30-$C$38)^2+(O30-$C$38)^2)/3) -> 0.027220741
A31: A4 | B31: K3 | C31: =Оценки!H27 -> 6 | D31: =Оценки!I27 -> 7 | E31: =Оценки!J27 -> 7 | F31: =$I$8 -> 9 | G31: =C31/F31 -> 0.66666667 | H31: =D31/F31 -> 0.77777778 | I31: =E31/F31 -> 0.77777778 | J31: =$F$8 -> 0.18421053 | K31: =$G$8 -> 0.21052632 | L31: =$H$8 -> 0.21052632 | M31: =G31*J31 -> 0.12280702 | N31: =H31*K31 -> 0.16374269 | O31: =I31*L31 -> 0.16374269 | P31: =SQRT(((M31-$B$39)^2+(N31-$B$39)^2+(O31-$B$39)^2)/3) -> 0.063435244 | Q31: =SQRT(((M31-$C$39)^2+(N31-$C$39)^2+(O31-$C$39)^2)/3) -> 0.033423837
A32: A4 | B32: K4 | C32: =Оценки!H28 -> 6 | D32: =Оценки!I28 -> 7 | E32: =Оценки!J28 -> 7 | F32: =$I$9 -> 9 | G32: =C32/F32 -> 0.66666667 | H32: =D32/F32 -> 0.77777778 | I32: =E32/F32 -> 0.77777778 | J32: =$F$9 -> 0.15789474 | K32: =$G$9 -> 0.18421053 | L32: =$H$9 -> 0.18421053 | M32: =G32*J32 -> 0.10526316 | N32: =H32*K32 -> 0.14327485 | O32: =I32*L32 -> 0.14327485 | P32: =SQRT(((M32-$B$40)^2+(N32-$B$40)^2+(O32-$B$40)^2)/3) -> 0.056521812 | Q32: =SQRT(((M32-$C$40)^2+(N32-$C$40)^2+(O32-$C$40)^2)/3) -> 0.03103642
A33: A4 | B33: K5 | C33: =Оценки!H29 -> 8 | D33: =Оценки!I29 -> 9 | E33: =Оценки!J29 -> 9 | F33: =$I$10 -> 9 | G33: =C33/F33 -> 0.88888889 | H33: =D33/F33 -> 1 | I33: =E33/F33 -> 1 | J33: =$F$10 -> 0.13157895 | K33: =$G$10 -> 0.15789474 | L33: =$H$10 -> 0.15789474 | M33: =G33*J33 -> 0.11695906 | N33: =H33*K33 -> 0.15789474 | O33: =I33*L33 -> 0.15789474 | P33: =SQRT(((M33-$B$41)^2+(N33-$B$41)^2+(O33-$B$41)^2)/3) -> 0.023634222 | Q33: =SQRT(((M33-$C$41)^2+(N33-$C$41)^2+(O33-$C$41)^2)/3) -> 0.087914014
A35: 3. FPIS/FNIS — положительный и отрицательный идеалы по каждому критерию
A36: Критерий | B36: Идеал +: max v(u) | C36: Идеал −: min v(l)
A37: K1 | B37: =MAX(O14,O19,O24,O29) -> 0.23684211 | C37: =MIN(M14,M19,M24,M29) -> 0.14035088
A38: K2 | B38: =MAX(O15,O20,O25,O30) -> 0.23684211 | C38: =MIN(M15,M20,M25,M30) -> 0.11695906
A39: K3 | B39: =MAX(O16,O21,O26,O31) -> 0.21052632 | C39: =MIN(M16,M21,M26,M31) -> 0.12280702
A40: K4 | B40: =MAX(O17,O22,O27,O32) -> 0.18421053 | C40: =MIN(M17,M22,M27,M32) -> 0.10526316
A41: K5 | B41: =MAX(O18,O23,O28,O33) -> 0.15789474 | C41: =MIN(M18,M23,M28,M33) -> 0.058479532
A43: 4. Итог: d+ / d− / коэффициент близости
A44: Альтернатива | B44: Концепция | C44: d+ | D44: d− | E44: CC=d−/(d++d−) | F44: Место
...

Sheet МАИ суждения
A1: Индивидуальные попарные сравнения МАИ
A3: Шкала Саати 1–9 и обратные значения. В колонке H — геометрическое среднее 3 суждений. Все входные суждения — учебный пример.
A4: Матрица | B4: Основание | C4: Слева | D4: Справа | E4: Участник 1 | F4: Участник 2 | G4: Участник 3 | H4: Группа (геом. сред.)
A5: Критерии | B5: Важность критериев | C5: K1 | D5: K2 | E5: 1 | F5: 1 | G5: 1 | H5: =(E5*F5*G5)^(1/3) -> 1
A6: Критерии | B6: Важность критериев | C6: K1 | D6: K3 | E6: 2 | F6: 2 | G6: 2 | H6: =(E6*F6*G6)^(1/3) -> 2
A7: Критерии | B7: Важность критериев | C7: K1 | D7: K4 | E7: 3 | F7: 3 | G7: 4 | H7: =(E7*F7*G7)^(1/3) -> 3.3019272
A8: Критерии | B8: Важность критериев | C8: K1 | D8: K5 | E8: 4 | F8: 3 | G8: 3 | H8: =(E8*F8*G8)^(1/3) -> 3.3019272
A9: Критерии | B9: Важность критериев | C9: K2 | D9: K3 | E9: 2 | F9: 2 | G9: 2 | H9: =(E9*F9*G9)^(1/3) -> 2
A10: Критерии | B10: Важность критериев | C10: K2 | D10: K4 | E10: 3 | F10: 3 | G10: 3 | H10: =(E10*F10*G10)^(1/3) -> 3
A11: Критерии | B11: Важность критериев | C11: K2 | D11: K5 | E11: 4 | F11: 4 | G11: 3 | H11: =(E11*F11*G11)^(1/3) -> 3.6342412
A12: Критерии | B12: Важность критериев | C12: K3 | D12: K4 | E12: 2 | F12: 2 | G12: 2 | H12: =(E12*F12*G12)^(1/3) -> 2
A13: Критерии | B13: Важность критериев | C13: K3 | D13: K5 | E13: 3 | F13: 2 | G13: 3 | H13: =(E13*F13*G13)^(1/3) -> 2.6207414
A14: Критерии | B14: Важность критериев | C14: K4 | D14: K5 | E14: 2 | F14: 2 | G14: 2 | H14: =(E14*F14*G14)^(1/3) -> 2
A15: K1 | B15: Ценность для студентов | C15: A1 | D15: A2 | E15: 0.5 | F15: 0.5 | G15: 0.5 | H15: =(E15*F15*G15)^(1/3) -> 0.5
A16: K1 | B16: Ценность для студентов | C16: A1 | D16: A3 | E16: 2 | F16: 1 | G16: 2 | H16: =(E16*F16*G16)^(1/3) -> 1.5874011
... A44: K5 | B44: Потенциал развития | C44: A3 | D44: A4 | E44: 0.5 | F44: 0.5 | G44: 0.5 | H44: =(E44*F44*G44)^(1/3) -> 0.5

Sheet МАИ матрицы
A1: Коллективные матрицы МАИ и проверка согласованности
A3: Матрица группы — геометрическое среднее индивидуальных попарных суждений; локальные приоритеты — нормированные геометрические средние строк.
A5: Критерии K1–K5
A6: Объект | B6: K1 | C6: K2 | D6: K3 | E6: K4 | F6: K5 | G6: Геом. | H6: Приоритет | I6: (Aw)/w
A7: K1 | B7: =1 -> 1 | C7: ='МАИ суждения'!H5 -> 1 | D7: ='МАИ суждения'!H6 -> 2 | E7: ='МАИ суждения'!H7 -> 3.3019272 | F7: ='МАИ суждения'!H8 -> 3.3019272 | G7: =(PRODUCT(B7:F7))^(1/5) -> 1.8523071 | H7: =G7/SUM($G$7:$G$11) -> 0.31776856 | I7: =(B7*$H$7+C7*$H$8+D7*$H$9+E7*$H$10+F7*$H$11)/H7 -> 5.0452148
A8: K2 | B8: =1/'МАИ суждения'!H5 -> 1 | C8: =1 -> 1 | D8: ='МАИ суждения'!H9 -> 2 | E8: ='МАИ суждения'!H10 -> 3 | F8: ='МАИ суждения'!H11 -> 3.6342412 | G8: =(PRODUCT(B8:F8))^(1/5) -> 1.8523071 | H8: =G8/SUM($G$7:$G$11) -> 0.31776856 | I8: =(B8*$H$7+C8*$H$8+D8*$H$9+E8*$H$10+F8*$H$11)/H8 -> 5.020536
A9: K3 | B9: =1/'МАИ суждения'!H6 -> 0.5 | C9: =1/'МАИ суждения'!H9 -> 0.5 | D9: =1 -> 1 | E9: ='МАИ суждения'!H12 -> 2 | F9: ='МАИ суждения'!H13 -> 2.6207414 | G9: =(PRODUCT(B9:F9))^(1/5) -> 1.0555501 | H9: =G9/SUM($G$7:$G$11) -> 0.18108262 | I9: =(B9*$H$7+C9*$H$8+D9*$H$9+E9*$H$10+F9*$H$11)/H9 -> 5.0370681
A10: K4 | B10: =1/'МАИ суждения'!H7 -> 0.30285343 | C10: =1/'МАИ суждения'!H10 -> 0.33333333 | D10: =1/'МАИ суждения'!H12 -> 0.5 | E10: =1 -> 1 | F10: ='МАИ суждения'!H14 -> 2 | G10: =(PRODUCT(B10:F10))^(1/5) -> 0.63215307 | H10: =G10/SUM($G$7:$G$11) -> 0.10844766 | I10: =(B10*$H$7+C10*$H$8+D10*$H$9+E10*$H$10+F10*$H$11)/H10 -> 5.0809242
A11: K5 | B11: =1/'МАИ суждения'!H8 -> 0.30285343 | C11: =1/'МАИ суждения'!H11 -> 0.2751606 | D11: =1/'МАИ суждения'!H13 -> 0.38157141 | E11: =1/'МАИ суждения'!H14 -> 0.5 | F11: =1 -> 1 | G11: =(PRODUCT(B11:F11))^(1/5) -> 0.43679023 | H11: =G11/SUM($G$7:$G$11) -> 0.074932607 | I11: =(B11*$H$7+C11*$H$8+D11*$H$9+E11*$H$10+F11*$H$11)/H11 -> 5.0969409
A13: λmax | B13: =AVERAGE(I7:I11) -> 5.0561368 | C13: CI | D13: =(B13-5)/(5-1) -> 0.014034207 | E13: CR | F13: =D13/1.12 -> 0.012530542 | G13: Статус | H13: =IF(F13<=0.1,"OK","Пересмотреть") -> OK
A18: Альтернативы по K1
A19: Объект | B19: A1 | C19: A2 | D19: A3 | E19: A4 | F19: Геом. | G19: Приоритет | H19: (Aw)/w
A20: A1 | B20: =1 -> 1 | C20: ='МАИ суждения'!H15 -> 0.5 | D20: ='МАИ суждения'!H16 -> 1.5874011 | E20: ='МАИ суждения'!H17 -> 0.62996052 | F20: =(PRODUCT(B20:E20))^(1/4) -> 0.84089642 | G20: =F20/SUM($F$20:$F$23) -> 0.19001263 | H20: =(B20*$G$20+C20*$G$21+D20*$G$22+E20*$G$23)/G20 -> 4.023545
A21: A2 | B21: =1/'МАИ суждения'!H15 -> 2 | C21: =1 -> 1 | D21: ='МАИ суждения'!H18 -> 3.3019272 | E21: ='МАИ суждения'!H19 -> 2 | F21: =(PRODUCT(B21:E21))^(1/4) -> 1.9063686 | G21: =F21/SUM($F$20:$F$23) -> 0.43077138 | H21: =(B21*$G$20+C21*$G$21+D21*$G$22+E21*$G$23)/G21 -> 4.022375
A22: A3 | B22: =1/'МАИ суждения'!H16 -> 0.62996052 | C22: =1/'МАИ суждения'!H18 -> 0.30285343 | D22: =1 -> 1 | E22: ='МАИ суждения'!H20 -> 0.5 | F22: =(PRODUCT(B22:E22))^(1/4) -> 0.55574935 | G22: =F22/SUM($F$20:$F$23) -> 0.12557955 | H22: =(B22*$G$20+C22*$G$21+D22*$G$22+E22*$G$23)/G22 -> 4.001916
A23: A4 | B23: =1/'МАИ суждения'!H17 -> 1.5874011 | C23: =1/'МАИ суждения'!H19 -> 0.5 | D23: =1/'МАИ суждения'!H20 -> 2 | E23: =1 -> 1 | F23: =(PRODUCT(B23:E23))^(1/4) -> 1.122462 | G23: =F23/SUM($F$20:$F$23) -> 0.25363643 | H23: =(B23*$G$20+C23*$G$21+D23*$G$22+E23*$G$23)/G23 -> 4.0286305
A25: λmax | B25: =AVERAGE(H20:H23) -> 4.0191166 | C25: CI | D25: =(B25-4)/(4-1) -> 0.0063722151 | E25: CR | F25: =D25/0.9 -> 0.007080239 | G25: Статус | H25: =IF(F25<=0.1,"OK","Пересмотреть") -> OK
A31: Альтернативы по K2
A32: Объект | B32: A1 | C32: A2 | D32: A3 | E32: A4 | F32: Геом. | G32: Приоритет | H32: (Aw)/w
A33: A1 | B33: =1 -> 1 | C33: ='МАИ суждения'!H21 -> 2 | D33: ='МАИ суждения'!H22 -> 1 | E33: ='МАИ суждения'!H23 -> 3.6342412 | F33: =(PRODUCT(B33:E33))^(1/4) -> 1.6419538 | G33: =F33/SUM($F$33:$F$36) -> 0.35618124 | H33: =(B33*$G$33+C33*$G$34+D33*$G$35+E33*$G$36)/G33 -> 4.0052417
A34: A2 | B34: =1/'МАИ суждения'!H21 -> 0.5 | C34: =1 -> 1 | D34: ='МАИ суждения'!H24 -> 0.5 | E34: ='МАИ суждения'!H25 -> 2.2894285 | F34: =(PRODUCT(B34:E34))^(1/4) -> 0.86979473 | G34: =F34/SUM($F$33:$F$36) -> 0.18868044 | H34: =(B34*$G$33+C34*$G$34+D34*$G$35+E34*$G$36)/G34 -> 4.0065227
A35: A3 | B35: =1/'МАИ суждения'!H22 -> 1 | C35: =1/'МАИ суждения'!H24 -> 2 | D35: =1 -> 1 | E35: ='МАИ суждения'!H26 -> 4 | F35: =(PRODUCT(B35:E35))^(1/4) -> 1.6817928 | G35: =F35/SUM($F$33:$F$36) -> 0.36482333 | H35: =(B35*$G$33+C35*$G$34+D35*$G$35+E35*$G$36)/G35 -> 4.0009104
A36: A4 | B36: =1/'МАИ суждения'!H23 -> 0.2751606 | C36: =1/'МАИ суждения'!H25 -> 0.43679023 | D36: =1/'МАИ суждения'!H26 -> 0.25 | E36: =1 -> 1 | F36: =(PRODUCT(B36:E36))^(1/4) -> 0.41634159 | G36: =F36/SUM($F$33:$F$36) -> 0.090315002 | H36: =(B36*$G$33+C36*$G$34+D36*$G$35+E36*$G$36)/G36 -> 4.0075474
A38: λmax | B38: =AVERAGE(H33:H36) -> 4.0050555 | C38: CI | D38: =(B38-4)/(4-1) -> 0.0016851829 | E38: CR | F38: =D38/0.9 -> 0.0018724254 | G38: Статус | H38: =IF(F38<=0.1,"OK","Пересмотреть") -> OK
A44: Альтернативы по K3
A45: Объект | B45: A1 | C45: A2 | D45: A3 | E45: A4 | F45: Геом. | G45: Приоритет | H45: (Aw)/w
A46: A1 | B46: =1 -> 1 | C46: ='МАИ суждения'!H27 -> 1 | D46: ='МАИ суждения'!H28 -> 2 | E46: ='МАИ суждения'!H29 -> 3.6342412 | F46: =(PRODUCT(B46:E46))^(1/4) -> 1.6419538 | G46: =F46/SUM($F$46:$F$49) -> 0.35500544 | H46: =(B46*$G$46+C46*$G$47+D46*$G$48+E46*$G$49)/G46 -> 4.0028801
A47: A2 | B47: =1/'МАИ суждения'!H27 -> 1 | C47: =1 -> 1 | D47: ='МАИ суждения'!H30 -> 2.2894285 | E47: ='МАИ суждения'!H31 -> 4 | F47: =(PRODUCT(B47:E47))^(1/4) -> 1.7395895 | G47: =F47/SUM($F$46:$F$49) -> 0.37611516 | H47: =(B47*$G$46+C47*$G$47+D47*$G$48+E47*$G$49)/G47 -> 4.0040203
A48: A3 | B48: =1/'МАИ суждения'!H28 -> 0.5 | C48: =1/'МАИ суждения'!H30 -> 0.43679023 | D48: =1 -> 1 | E48: ='МАИ суждения'!H32 -> 2 | F48: =(PRODUCT(B48:E48))^(1/4) -> 0.81295823 | G48: =F48/SUM($F$46:$F$49) -> 0.17576901 | H48: =(B48*$G$46+C48*$G$47+D48*$G$48+E48*$G$49)/G48 -> 4.0039819
A49: A4 | B49: =1/'МАИ суждения'!H29 -> 0.2751606 | C49: =1/'МАИ суждения'!H31 -> 0.25 | D49: =1/'МАИ суждения'!H32 -> 0.5 | E49: =1 -> 1 | F49: =(PRODUCT(B49:E49))^(1/4) -> 0.43064962 | G49: =F49/SUM($F$46:$F$49) -> 0.093110389 | H49: =(B49*$G$46+C49*$G$47+D49*$G$48+E49*$G$49)/G49 -> 4.002853
A51: λmax | B51: =AVERAGE(H46:H49) -> 4.0034338 | C51: CI | D51: =(B51-4)/(4-1) -> 0.0011446091 | E51: CR | F51: =D51/0.9 -> 0.0012717879 | G51: Статус | H51: =IF(F51<=0.1,"OK","Пересмотреть") -> OK
A57: Альтернативы по K4
A58: Объект | B58: A1 | C58: A2 | D58: A3 | E58: A4 | F58: Геом. | G58: Приоритет | H58: (Aw)/w
A59: A1 | B59: =1 -> 1 | C59: ='МАИ суждения'!H33 -> 1 | D59: ='МАИ суждения'!H34 -> 2 | E59: ='МАИ суждения'!H35 -> 3.3019272 | F59: =(PRODUCT(B59:E59))^(1/4) -> 1.6030585 | G59: =F59/SUM($F$59:$F$62) -> 0.35546296 | H59: =(B59*$G$59+C59*$G$60+D59*$G$61+E59*$G$62)/G59 -> 4.0022994
A60: A2 | B60: =1/'МАИ суждения'!H33 -> 1 | C60: =1 -> 1 | D60: ='МАИ суждения'!H36 -> 2 | E60: ='МАИ суждения'!H37 -> 3.3019272 | F60: =(PRODUCT(B60:E60))^(1/4) -> 1.6030585 | G60: =F60/SUM($F$59:$F$62) -> 0.35546296 | H60: =(B60*$G$59+C60*$G$60+D60*$G$61+E60*$G$62)/G60 -> 4.0022994
A61: A3 | B61: =1/'МАИ суждения'!H34 -> 0.5 | C61: =1/'МАИ суждения'!H36 -> 0.5 | D61: =1 -> 1 | E61: ='МАИ суждения'!H38 -> 2 | F61: =(PRODUCT(B61:E61))^(1/4) -> 0.84089642 | G61: =F61/SUM($F$59:$F$62) -> 0.18646077 | H61: =(B61*$G$59+C61*$G$60+D61*$G$61+E61*$G$62)/G61 -> 4.007011
A62: A4 | B62: =1/'МАИ суждения'!H35 -> 0.30285343 | C62: =1/'МАИ суждения'!H37 -> 0.30285343 | D62: =1/'МАИ суждения'!H38 -> 0.5 | E62: =1 -> 1 | F62: =(PRODUCT(B62:E62))^(1/4) -> 0.46276313 | G62: =F62/SUM($F$59:$F$62) -> 0.10261332 | H62: =(B62*$G$59+C62*$G$60+D62*$G$61+E62*$G$62)/G62 -> 4.0067904
A64: λmax | B64: =AVERAGE(H59:H62) -> 4.0046 | C64: CI | D64: =(B64-4)/(4-1) -> 0.0015333449 | E64: CR | F64: =D64/0.9 -> 0.0017037165 | G64: Статус | H64: =IF(F64<=0.1,"OK","Пересмотреть") -> OK
A70: Альтернативы по K5
A71: Объект | B71: A1 | C71: A2 | D71: A3 | E71: A4 | F71: Геом. | G71: Приоритет | H71: (Aw)/w
...

Sheet МАИ проверки
A1: Аудит: индивидуальные матрицы 3 экспертов
A3: Каждая матрица строится из собственных суждений участника. CR должен быть не выше 0,10.
A5: Участник 1 | Критерии K1–K5
A6: Объект | B6: K1 | C6: K2 | D6: K3 | E6: K4 | F6: K5 | G6: Геом. | H6: Приоритет | I6: (Aw)/w
A7: K1 | B7: =1 -> 1 | C7: ='МАИ суждения'!E5 -> 1 | D7: ='МАИ суждения'!E6 -> 2 | E7: ='МАИ суждения'!E7 -> 3 | F7: ='МАИ суждения'!E8 -> 4 | G7: =(PRODUCT(B7:F7))^(1/5) -> 1.888175 | H7: =G7/SUM($G$7:$G$11) -> 0.31967279 | I7: =(B7*$H$7+C7*$H$8+D7*$H$9+E7*$H$10+F7*$H$11)/H7 -> 5.0228176
A8: K2 | B8: =1/'МАИ суждения'!E5 -> 1 | C8: =1 -> 1 | D8: ='МАИ суждения'!E9 -> 2 | E8: ='МАИ суждения'!E10 -> 3 | F8: ='МАИ суждения'!E11 -> 4 | G8: =(PRODUCT(B8:F8))^(1/5) -> 1.888175 | H8: =G8/SUM($G$7:$G$11) -> 0.31967279 | I8: =(B8*$H$7+C8*$H$8+D8*$H$9+E8*$H$10+F8*$H$11)/H8 -> 5.0228176
A9: K3 | B9: =1/'МАИ суждения'!E6 -> 0.5 | C9: =1/'МАИ суждения'!E9 -> 0.5 | D9: =1 -> 1 | E9: ='МАИ суждения'!E12 -> 2 | F9: ='МАИ суждения'!E13 -> 3 | G9: =(PRODUCT(B9:F9))^(1/5) -> 1.0844718 | H9: =G9/SUM($G$7:$G$11) -> 0.1836038 | I9: =(B9*$H$7+C9*$H$8+D9*$H$9+E9*$H$10+F9*$H$11)/H9 -> 5.0398243
A10: K4 | B10: =1/'МАИ суждения'!E7 -> 0.33333333 | C10: =1/'МАИ суждения'!E10 -> 0.33333333 | D10: =1/'МАИ суждения'!E12 -> 0.5 | E10: =1 -> 1 | F10: ='МАИ суждения'!E14 -> 2 | G10: =(PRODUCT(B10:F10))^(1/5) -> 0.64439401 | H10: =G10/SUM($G$7:$G$11) -> 0.10909753 | I10: =(B10*$H$7+C10*$H$8+D10*$H$9+E10*$H$10+F10*$H$11)/H10 -> 5.0406347
A11: K5 | B11: =1/'МАИ суждения'!E8 -> 0.25 | C11: =1/'МАИ суждения'!E11 -> 0.25 | D11: =1/'МАИ суждения'!E13 -> 0.33333333 | E11: =1/'МАИ суждения'!E14 -> 0.5 | F11: =1 -> 1 | G11: =(PRODUCT(B11:F11))^(1/5) -> 0.40137078 | H11: =G11/SUM($G$7:$G$11) -> 0.067953085 | I11: =(B11*$H$7+C11*$H$8+D11*$H$9+E11*$H$10+F11*$H$11)/H11 -> 5.0555396
A13: λmax | B13: =AVERAGE(I7:I11) -> 5.0363268 | C13: CI | D13: =(B13-5)/(5-1) -> 0.0090816902 | E13: CR | F13: =D13/1.12 -> 0.0081086519 | G13: Статус | H13: =IF(F13<=0.1,"OK","Пересмотреть") -> OK
A18: Участник 1 | Альтернативы по K1
A19: Объект | B19: A1 | C19: A2 | D19: A3 | E19: A4 | F19: Геом. | G19: Приоритет | H19: (Aw)/w
A20: A1 | B20: =1 -> 1 | C20: ='МАИ суждения'!E15 -> 0.5 | D20: ='МАИ суждения'!E16 -> 2 | E20: ='МАИ суждения'!E17 -> 1 | F20: =(PRODUCT(B20:E20))^(1/4) -> 1 | G20: =F20/SUM($F$20:$F$23) -> 0.22735051 | H20: =(B20*$G$20+C20*$G$21+D20*$G$22+E20*$G$23)/G20 -> 4.0051748
A21: A2 | B21: =1/'МАИ суждения'!E15 -> 2 | C21: =1 -> 1 | D21: ='МАИ суждения'!E18 -> 3 | E21: ='МАИ суждения'!E19 -> 2 | F21: =(PRODUCT(B21:E21))^(1/4) -> 1.8612097 | G21: =F21/SUM($F$20:$F$23) -> 0.42314697 | H21: =(B21*$G$20+C21*$G$21+D21*$G$22+E21*$G$23)/G21 -> 4.0151653
A22: A3 | B22: =1/'МАИ суждения'!E16 -> 0.5 | C22: =1/'МАИ суждения'!E18 -> 0.33333333 | D22: =1 -> 1 | E22: ='МАИ суждения'!E20 -> 0.5 | F22: =(PRODUCT(B22:E22))^(1/4) -> 0.53728497 | G22: =F22/SUM($F$20:$F$23) -> 0.12215201 | H22: =(B22*$G$20+C22*$G$21+D22*$G$22+E22*$G$23)/G22 -> 4.0159103
A23: A4 | B23: =1/'МАИ суждения'!E17 -> 1 | C23: =1/'МАИ суждения'!E19 -> 0.5 | D23: =1/'МАИ суждения'!E20 -> 2 | E23: =1 -> 1 | F23: =(PRODUCT(B23:E23))^(1/4) -> 1 | G23: =F23/SUM($F$20:$F$23) -> 0.22735051 | H23: =(B23*$G$20+C23*$G$21+D23*$G$22+E23*$G$23)/G23 -> 4.0051748
A25: λmax | B25: =AVERAGE(H20:H23) -> 4.0103563 | C25: CI | D25: =(B25-4)/(4-1) -> 0.0034520922 | E25: CR | F25: =D25/0.9 -> 0.003835658 | G25: Статус | H25: =IF(F25<=0.1,"OK","Пересмотреть") -> OK
A31: Участник 1 | Альтернативы по K2
A32: Объект | B32: A1 | C32: A2 | D32: A3 | E32: A4 | F32: Геом. | G32: Приоритет | H32: (Aw)/w
A33: A1 | B33: =1 -> 1 | C33: ='МАИ суждения'!E21 -> 2 | D33: ='МАИ суждения'!E22 -> 1 | E33: ='МАИ суждения'!E23 -> 4 | F33: =(PRODUCT(B33:E33))^(1/4) -> 1.6817928 | G33: =F33/SUM($F$33:$F$36) -> 0.36363636 | H33: =(B33*$G$33+C33*$G$34+D33*$G$35+E33*$G$36)/G33 -> 4
A34: A2 | B34: =1/'МАИ суждения'!E21 -> 0.5 | C34: =1 -> 1 | D34: ='МАИ суждения'!E24 -> 0.5 | E34: ='МАИ суждения'!E25 -> 2 | F34: =(PRODUCT(B34:E34))^(1/4) -> 0.84089642 | G34: =F34/SUM($F$33:$F$36) -> 0.18181818 | H34: =(B34*$G$33+C34*$G$34+D34*$G$35+E34*$G$36)/G34 -> 4
A35: A3 | B35: =1/'МАИ суждения'!E22 -> 1 | C35: =1/'МАИ суждения'!E24 -> 2 | D35: =1 -> 1 | E35: ='МАИ суждения'!E26 -> 4 | F35: =(PRODUCT(B35:E35))^(1/4) -> 1.6817928 | G35: =F35/SUM($F$33:$F$36) -> 0.36363636 | H35: =(B35*$G$33+C35*$G$34+D35*$G$35+E35*$G$36)/G35 -> 4
A36: A4 | B36: =1/'МАИ суждения'!E23 -> 0.25 | C36: =1/'МАИ суждения'!E25 -> 0.5 | D36: =1/'МАИ суждения'!E26 -> 0.25 | E36: =1 -> 1 | F36: =(PRODUCT(B36:E36))^(1/4) -> 0.42044821 | G36: =F36/SUM($F$33:$F$36) -> 0.090909091 | H36: =(B36*$G$33+C36*$G$34+D36*$G$35+E36*$G$36)/G36 -> 4
A38: λmax | B38: =AVERAGE(H33:H36) -> 4 | C38: CI | D38: =(B38-4)/(4-1) -> 0 | E38: CR | F38: =D38/0.9 -> 0 | G38: Статус | H38: =IF(F38<=0.1,"OK","Пересмотреть") -> OK
A44: Участник 1 | Альтернативы по K3
A45: Объект | B45: A1 | C45: A2 | D45: A3 | E45: A4 | F45: Геом. | G45: Приоритет | H45: (Aw)/w
A46: A1 | B46: =1 -> 1 | C46: ='МАИ суждения'!E27 -> 1 | D46: ='МАИ суждения'!E28 -> 2 | E46: ='МАИ суждения'!E29 -> 4 | F46: =(PRODUCT(B46:E46))^(1/4) -> 1.6817928 | G46: =F46/SUM($F$46:$F$49) -> 0.36363636 | H46: =(B46*$G$46+C46*$G$47+D46*$G$48+E46*$G$49)/G46 -> 4
A47: A2 | B47: =1/'МАИ суждения'!E27 -> 1 | C47: =1 -> 1 | D47: ='МАИ суждения'!E30 -> 2 | E47: ='МАИ суждения'!E31 -> 4 | F47: =(PRODUCT(B47:E47))^(1/4) -> 1.6817928 | G47: =F47/SUM($F$46:$F$49) -> 0.36363636 | H47: =(B47*$G$46+C47*$G$47+D47*$G$48+E47*$G$49)/G47 -> 4
A48: A3 | B48: =1/'МАИ суждения'!E28 -> 0.5 | C48: =1/'МАИ суждения'!E30 -> 0.5 | D48: =1 -> 1 | E48: ='МАИ суждения'!E32 -> 2 | F48: =(PRODUCT(B48:E48))^(1/4) -> 0.84089642 | G48: =F48/SUM($F$46:$F$49) -> 0.18181818 | H48: =(B48*$G$46+C48*$G$47+D48*$G$48+E48*$G$49)/G48 -> 4
A49: A4 | B49: =1/'МАИ суждения'!E29 -> 0.25 | C49: =1/'МАИ суждения'!E31 -> 0.25 | D49: =1/'МАИ суждения'!E32 -> 0.5 | E49: =1 -> 1 | F49: =(PRODUCT(B49:E49))^(1/4) -> 0.42044821 | G49: =F49/SUM($F$46:$F$49) -> 0.090909091 | H49: =(B49*$G$46+C49*$G$47+D49*$G$48+E49*$G$49)/G49 -> 4
A51: λmax | B51: =AVERAGE(H46:H49) -> 4 | C51: CI | D51: =(B51-4)/(4-1) -> 0 | E51: CR | F51: =D51/0.9 -> 0 | G51: Статус | H51: =IF(F51<=0.1,"OK","Пересмотреть") -> OK
A57: Участник 1 | Альтернативы по K4
A58: Объект | B58: A1 | C58: A2 | D58: A3 | E58: A4 | F58: Геом. | G58: Приоритет | H58: (Aw)/w
A59: A1 | B59: =1 -> 1 | C59: ='МАИ суждения'!E33 -> 1 | D59: ='МАИ суждения'!E34 -> 2 | E59: ='МАИ суждения'!E35 -> 3 | F59: =(PRODUCT(B59:E59))^(1/4) -> 1.5650846 | G59: =F59/SUM($F$59:$F$62) -> 0.3511869 | H59: =(B59*$G$59+C59*$G$60+D59*$G$61+E59*$G$62)/G59 -> 4.0051748
A60: A2 | B60: =1/'МАИ суждения'!E33 -> 1 | C60: =1 -> 1 | D60: ='МАИ суждения'!E36 -> 2 | E60: ='МАИ суждения'!E37 -> 3 | F60: =(PRODUCT(B60:E60))^(1/4) -> 1.5650846 | G60: =F60/SUM($F$59:$F$62) -> 0.3511869 | H60: =(B60*$G$59+C60*$G$60+D60*$G$61+E60*$G$62)/G60 -> 4.0051748
A61: A3 | B61: =1/'МАИ суждения'!E34 -> 0.5 | C61: =1/'МАИ суждения'!E36 -> 0.5 | D61: =1 -> 1 | E61: ='МАИ суждения'!E38 -> 2 | F61: =(PRODUCT(B61:E61))^(1/4) -> 0.84089642 | G61: =F61/SUM($F$59:$F$62) -> 0.18868744 | H61: =(B61*$G$59+C61*$G$60+D61*$G$61+E61*$G$62)/G61 -> 4.0159103
A62: A4 | B62: =1/'МАИ суждения'!E35 -> 0.33333333 | C62: =1/'МАИ суждения'!E37 -> 0.33333333 | D62: =1/'МАИ суждения'!E38 -> 0.5 | E62: =1 -> 1 | F62: =(PRODUCT(B62:E62))^(1/4) -> 0.48549177 | G62: =F62/SUM($F$59:$F$62) -> 0.10893875 | H62: =(B62*$G$59+C62*$G$60+D62*$G$61+E62*$G$62)/G62 -> 4.0151653
A64: λmax | B64: =AVERAGE(H59:H62) -> 4.0103563 | C64: CI | D64: =(B64-4)/(4-1) -> 0.0034520922 | E64: CR | F64: =D64/0.9 -> 0.003835658 | G64: Статус | H64: =IF(F64<=0.1,"OK","Пересмотреть") -> OK
A70: Участник 1 | Альтернативы по K5
A71: Объект | B71: A1 | C71: A2 | D71: A3 | E71: A4 | F71: Геом. | G71: Приоритет | H71: (Aw)/w
...

Sheet МАИ итог
A1: Коллективный МАИ — синтез приоритетов
A3: 1. Веса критериев (коллективная матрица)
A4: Критерий | B4: Вес (МАИ) | C4: Описание
A5: K1 | B5: ='МАИ матрицы'!H7 -> 0.31776856 | C5: Ценность для студентов
A6: K2 | B6: ='МАИ матрицы'!H8 -> 0.31776856 | C6: Реализуемость MVP
A7: K3 | B7: ='МАИ матрицы'!H9 -> 0.18108262 | C7: Проверяемость и демо
A8: K4 | B8: ='МАИ матрицы'!H10 -> 0.10844766 | C8: Доступность тестовых данных
A9: K5 | B9: ='МАИ матрицы'!H11 -> 0.074932607 | C9: Потенциал развития
A10: Проверка Σ | B10: =SUM(B5:B9) -> 1
A11: 2. Локальные приоритеты и общий итог
A12: Код | B12: Концепция | C12: K1 | D12: K2 | E12: K3 | F12: K4 | G12: K5 | H12: Итоговый вес | I12: Место
A13: A1 | B13: StudyFlow | C13: ='МАИ матрицы'!G20 -> 0.19001263 | D13: ='МАИ матрицы'!G33 -> 0.35618124 | E13: ='МАИ матрицы'!G46 -> 0.35500544 | F13: ='МАИ матрицы'!G59 -> 0.35546296 | G13: ='МАИ матрицы'!G72 -> 0.085021176 | H13: =C13*$B$5+D13*$B$6+E13*$B$7+F13*$B$8+G13*$B$9 -> 0.28276854 | I13: =RANK(H13,$H$13:$H$16,0) -> 2
A14: A2 | B14: CampusEvents | C14: ='МАИ матрицы'!G21 -> 0.43077138 | D14: ='МАИ матрицы'!G34 -> 0.18868044 | E14: ='МАИ матрицы'!G47 -> 0.37611516 | F14: ='МАИ матрицы'!G60 -> 0.35546296 | G14: ='МАИ матрицы'!G73 -> 0.37069052 | H14: =C14*$B$5+D14*$B$6+E14*$B$7+F14*$B$8+G14*$B$9 -> 0.33127616 | I14: =RANK(H14,$H$13:$H$16,0) -> 1
A15: A3 | B15: BookSwap | C15: ='МАИ матрицы'!G22 -> 0.12557955 | D15: ='МАИ матрицы'!G35 -> 0.36482333 | E15: ='МАИ матрицы'!G48 -> 0.17576901 | F15: ='МАИ матрицы'!G61 -> 0.18646077 | G15: ='МАИ матрицы'!G74 -> 0.17918729 | H15: =C15*$B$5+D15*$B$6+E15*$B$7+F15*$B$8+G15*$B$9 -> 0.22131153 | I15: =RANK(H15,$H$13:$H$16,0) -> 3
A16: A4 | B16: SkillBridge | C16: ='МАИ матрицы'!G23 -> 0.25363643 | D16: ='МАИ матрицы'!G36 -> 0.090315002 | E16: ='МАИ матрицы'!G49 -> 0.093110389 | F16: ='МАИ матрицы'!G62 -> 0.10261332 | G16: ='МАИ матрицы'!G75 -> 0.36510101 | H16: =C16*$B$5+D16*$B$6+E16*$B$7+F16*$B$8+G16*$B$9 -> 0.16464377 | I16: =RANK(H16,$H$13:$H$16,0) -> 4
B18: Проверка суммы | H18: =SUM(H13:H16) -> 1
A20: 3. Индекс согласованности (CR): групповые матрицы
A21: Матрица | B21: CR | C21: Контроль
A22: Критерии | B22: ='МАИ матрицы'!F13 -> 0.012530542 | C22: =IF(B22<=0.1,"OK","Пересмотреть") -> OK
A23: K1 | B23: ='МАИ матрицы'!F25 -> 0.007080239 | C23: =IF(B23<=0.1,"OK","Пересмотреть") -> OK
A24: K2 | B24: ='МАИ матрицы'!F38 -> 0.0018724254 | C24: =IF(B24<=0.1,"OK","Пересмотреть") -> OK
A25: K3 | B25: ='МАИ матрицы'!F51 -> 0.0012717879 | C25: =IF(B25<=0.1,"OK","Пересмотреть") -> OK
A26: K4 | B26: ='МАИ матрицы'!F64 -> 0.0017037165 | C26: =IF(B26<=0.1,"OK","Пересмотреть") -> OK
A27: K5 | B27: ='МАИ матрицы'!F77 -> 0.0023293921 | C27: =IF(B27<=0.1,"OK","Пересмотреть") -> OK
A29: 4. Проверка согласованности отдельных экспертов
A30: Эксперт | B30: Матрица | C30: CR | D30: Контроль
A31: Участник 1 | B31: Критерии | C31: ='МАИ проверки'!F13 -> 0.0081086519 | D31: =IF(C31<=0.1,"OK","Пересмотреть") -> OK
A32: Участник 1 | B32: K1 | C32: ='МАИ проверки'!F25 -> 0.003835658 | D32: =IF(C32<=0.1,"OK","Пересмотреть") -> OK
A33: Участник 1 | B33: K2 | C33: ='МАИ проверки'!F38 -> 0 | D33: =IF(C33<=0.1,"OK","Пересмотреть") -> OK
A34: Участник 1 | B34: K3 | C34: ='МАИ проверки'!F51 -> 0 | D34: =IF(C34<=0.1,"OK","Пересмотреть") -> OK
A35: Участник 1 | B35: K4 | C35: ='МАИ проверки'!F64 -> 0.003835658 | D35: =IF(C35<=0.1,"OK","Пересмотреть") -> OK
A36: Участник 1 | B36: K5 | C36: ='МАИ проверки'!F77 -> 0 | D36: =IF(C36<=0.1,"OK","Пересмотреть") -> OK
A37: Участник 2 | B37: Критерии | C37: ='МАИ проверки'!F91 -> 0.013096703 | D37: =IF(C37<=0.1,"OK","Пересмотреть") -> OK
A38: Участник 2 | B38: K1 | C38: ='МАИ проверки'!F103 -> 0.016922922 | D38: =IF(C38<=0.1,"OK","Пересмотреть") -> OK
A39: Участник 2 | B39: K2 | C39: ='МАИ проверки'!F116 -> 0.0076275135 | D39: =IF(C39<=0.1,"OK","Пересмотреть") -> OK
A40: Участник 2 | B40: K3 | C40: ='МАИ проверки'!F129 -> 0.003835658 | D40: =IF(C40<=0.1,"OK","Пересмотреть") -> OK
A41: Участник 2 | B41: K4 | C41: ='МАИ проверки'!F142 -> 0.003835658 | D41: =IF(C41<=0.1,"OK","Пересмотреть") -> OK
A42: Участник 2 | B42: K5 | C42: ='МАИ проверки'!F155 -> 0.0076275135 | D42: =IF(C42<=0.1,"OK","Пересмотреть") -> OK
A43: Участник 3 | B43: Критерии | C43: ='МАИ проверки'!F169 -> 0.023864874 | D43: =IF(C43<=0.1,"OK","Пересмотреть") -> OK
A44: Участник 3 | B44: K1 | C44: ='МАИ проверки'!F181 -> 0.022382821 | D44: =IF(C44<=0.1,"OK","Пересмотреть") -> OK
...

Sheet Задачи
A1: Декомпозиция работ фазы 1 — ПЛАН
A4: ID | B4: Задача | C4: Начало | D4: Окончание | E4: У1, ч | F4: У2, ч | G4: У3, ч | H4: Всего, чел·ч | I4: Статус | J4: Артефакт
A5: T01 | B5: Установочная встреча, правила и роли | C5: 46309 | D5: 46309 | E5: 0.5 | F5: 0.5 | G5: 0.5 | H5: =SUM(E5:G5) -> 1.5 | I5: Выполнено | J5: Протокол встречи
A6: T02 | B6: Концепция и 12 UC StudyFlow | C6: 46309 | D6: 46309 | E6: 1.4 | F6: 0 | G6: 0 | H6: =SUM(E6:G6) -> 1.4 | I6: Выполнено | J6: Паспорт A1
A7: T03 | B7: Концепция и 12 UC CampusEvents | C7: 46309 | D7: 46309 | E7: 0 | F7: 1.4 | G7: 0 | H7: =SUM(E7:G7) -> 1.4 | I7: Выполнено | J7: Паспорт A2
A8: T04 | B8: Концепция и 12 UC BookSwap | C8: 46310 | D8: 46310 | E8: 0.4 | F8: 0 | G8: 1 | H8: =SUM(E8:G8) -> 1.4 | I8: Выполнено | J8: Паспорт A3
A9: T05 | B9: Концепция и 12 UC SkillBridge | C9: 46310 | D9: 46310 | E9: 0 | F9: 0.4 | G9: 1 | H9: =SUM(E9:G9) -> 1.4 | I9: Выполнено | J9: Паспорт A4
A10: T06 | B10: Критерии, шкала и формулировки | C10: 46310 | D10: 46310 | E10: 1.1 | F10: 0.4 | G10: 0.4 | H10: =SUM(E10:G10) -> 1.9 | I10: Выполнено | J10: Критерии K1–K5
A11: T07 | B11: Независимые балльные оценки (TOPSIS) | C11: 46310 | D11: 46311 | E11: 0.8 | F11: 0.8 | G11: 0.8 | H11: =SUM(E11:G11) -> 2.4 | I11: Выполнено | J11: 3 опросных листа
A12: T08 | B12: Расчёт коллективного нечёткого TOPSIS | C12: 46311 | D12: 46312 | E12: 0.2 | F12: 2.2 | G12: 0.3 | H12: =SUM(E12:G12) -> 2.7 | I12: Выполнено | J12: Таблица TOPSIS
A13: T09 | B13: Независимые попарные сравнения МАИ | C13: 46311 | D13: 46312 | E13: 1.2 | F13: 1.2 | G13: 1.2 | H13: =SUM(E13:G13) -> 3.6 | I13: Выполнено | J13: 3 комплекта суждений
A14: T10 | B14: Агрегация МАИ и проверка CR | C14: 46312 | D14: 46313 | E14: 0.2 | F14: 0.3 | G14: 2.3 | H14: =SUM(E14:G14) -> 2.8 | I14: Выполнено | J14: Матрицы МАИ
A15: T11 | B15: Сопоставление и анализ чувствительности | C15: 46313 | D15: 46313 | E15: 0.4 | F15: 0.9 | G15: 0.7 | H15: =SUM(E15:G15) -> 2 | I15: Выполнено | J15: Сравнительная таблица
A16: T12 | B16: Общая встреча и решение команды | C16: 46313 | D16: 46313 | E16: 0.5 | F16: 0.5 | G16: 0.5 | H16: =SUM(E16:G16) -> 1.5 | I16: Выполнено | J16: Протокол выбора
... A19: T15 | B19: Публикация материалов в общей папке | C19: 46314 | D19: 46314 | E19: 0.4 | F19: 0 | G19: 0 | H19: =SUM(E19:G19) -> 0.4 | I19: Выполнено | J19: Ссылка на архив
B20: ИТОГО | E20: =SUM(E5:E19) -> 9.7 | F20: =SUM(F5:F19) -> 9.6 | G20: =SUM(G5:G19) -> 10 | H20: =SUM(H5:H19) -> 29.3

Sheet RACI
A1: Единая матрица RACI — версия 1 / фаза 1
A3: A — отвечает за результат; R — выполняет; C — консультирует; I — информируется. Одна A на каждую задачу. Новые фазы добавляются ниже.
A4: ID | B4: Работа | C4: Участник 1 | D4: Участник 2 | E4: Участник 3 | F4: Основание назначения
A5: T01 | B5: Установочная встреча, правила и роли | C5: A/R | D5: R | E5: R | F5: Координатор У1 ведёт протокол, все участвуют
A6: T02 | B6: Концепция и 12 UC StudyFlow | C6: A/R | D6: I | E6: I | F6: У1 — контент и декомпозиция
A7: T03 | B7: Концепция и 12 UC CampusEvents | C7: I | D7: A/R | E7: I | F7: У2 — альтернатива и предметные сценарии
A8: T04 | B8: Концепция и 12 UC BookSwap | C8: C | D8: I | E8: A/R | F8: У3 — владелец концепции, У1 проверяет
A9: T05 | B9: Концепция и 12 UC SkillBridge | C9: I | D9: C | E9: A/R | F9: У3 — владелец концепции, У2 проверяет
A10: T06 | B10: Критерии, шкала и формулировки | C10: A/R | D10: C | E10: C | F10: У1 унифицирует критерии, У2 и У3 проверяют
A11: T07 | B11: Независимые балльные оценки (TOPSIS) | C11: R | D11: A/R | E11: R | F11: Каждый выставляет оценки самостоятельно
A12: T08 | B12: Расчёт коллективного нечёткого TOPSIS | C12: C | D12: A/R | E12: C | F12: У2 ведёт численный TOPSIS
A13: T09 | B13: Независимые попарные сравнения МАИ | C13: R | D13: R | E13: A/R | F13: Каждый заполняет парные сравнения; У3 собирает
A14: T10 | B14: Агрегация МАИ и проверка CR | C14: C | D14: C | E14: A/R | F14: У3 рассчитывает и проверяет МАИ
A15: T11 | B15: Сопоставление и анализ чувствительности | C15: C | D15: A/R | E15: R | F15: У2 сравнивает результаты, У3 выполняет часть анализа
... A19: T15 | B19: Публикация материалов в общей папке | C19: A/R | D19: I | E19: I | F19: У1 публикует единую версию артефактов

Sheet Обзор
A1: Фаза 1 | Выбор концепции проекта
A5: Исходные ограничения
A6: Участников | B6: 3
A7: Концепций | B7: 4
A8: Use Cases для каждой | B8: 12
A9: Критериев | B9: 5
A10: Итоги ранжирования
A11: Концепция | B11: TOPSIS: CC | C11: Место | D11: МАИ: вес | E11: Место
A12: StudyFlow | B12: =TOPSIS!E45 -> 0.58731097 | C12: =TOPSIS!F45 -> 2 | D12: ='МАИ итог'!H13 -> 0.28276854 | E12: ='МАИ итог'!I13 -> 2
A13: CampusEvents | B13: =TOPSIS!E46 -> 0.70407472 | C13: =TOPSIS!F46 -> 1 | D13: ='МАИ итог'!H14 -> 0.33127616 | E13: ='МАИ итог'!I14 -> 1
A14: BookSwap | B14: =TOPSIS!E47 -> 0.55783568 | C14: =TOPSIS!F47 -> 3 | D14: ='МАИ итог'!H15 -> 0.22131153 | E14: ='МАИ итог'!I15 -> 3
A15: SkillBridge | B15: =TOPSIS!E48 -> 0.4505495 | C15: =TOPSIS!F48 -> 4 | D15: ='МАИ итог'!H16 -> 0.16464377 | E15: ='МАИ итог'!I16 -> 4
A18: Плановая трудоёмкость фазы
A19: Участник 1 | B19: =Задачи!E20 -> 9.7
A20: Участник 2 | B20: =Задачи!F20 -> 9.6
A21: Участник 3 | B21: =Задачи!G20 -> 10
A22: Суммарно, чел·ч | B22: =Задачи!H20 -> 29.3
A25: Редактировать: лист «Оценки» (E:G), лист «МАИ суждения» (E:G), лист «Задачи» (даты/часы/статусы). Расчётные столбцы связаны формулами.

Sheet Источники
A1: Методика и ссылки
A4: Источник | B4: URL / применение
A5: Chen, C.-T. (2000) | B5: https://doi.org/10.1016/S0165-0114(97)00377-1 — fuzzy TOPSIS, треугольные числа, вершинное расстояние
A6: Fuzzy TOPSIS (open access) | B6: https://pmc.ncbi.nlm.nih.gov/articles/PMC4864887/ — вычисление vertex distance
A7: AHP, групповое решение | B7: https://link.springer.com/article/10.1007/s10726-015-9448-4 — агрегирование оценок геометрическим средним
A8: AHP, согласованность | B8: https://pmc.ncbi.nlm.nih.gov/articles/PMC2650240/ — CR ≤ 0,10
A9: Статус | B9: Все экспертные оценки и пары — модельный пример; демонстрационная методика, не реальные протоколы участников
